<sdf version='1.7'>
  <world name='default'>
    <light name='sun' type='directional'>
      <cast_shadows>1</cast_shadows>
      <pose>0 0 10 0 -0 0</pose>
      <diffuse>0.8 0.8 0.8 1</diffuse>
      <specular>0.2 0.2 0.2 1</specular>
      <attenuation>
        <range>1000</range>
        <constant>0.9</constant>
        <linear>0.01</linear>
        <quadratic>0.001</quadratic>
      </attenuation>
      <direction>-0.5 0.1 -0.9</direction>
      <spot>
        <inner_angle>0</inner_angle>
        <outer_angle>0</outer_angle>
        <falloff>0</falloff>
      </spot>
    </light>
    <model name='ground_plane'>
      <static>1</static>
      <link name='link'>
        <collision name='collision'>
          <geometry>
            <plane>
              <normal>0 0 1</normal>
              <size>100 100</size>
            </plane>
          </geometry>
          <surface>
            <friction>
              <ode>
                <mu>100</mu>
                <mu2>50</mu2>
              </ode>
              <torsional>
                <ode/>
              </torsional>
            </friction>
            <contact>
              <ode/>
            </contact>
            <bounce/>
          </surface>
          <max_contacts>10</max_contacts>
        </collision>
        <visual name='visual'>
          <cast_shadows>0</cast_shadows>
          <geometry>
            <plane>
              <normal>0 0 1</normal>
              <size>100 100</size>
            </plane>
          </geometry>
          <material>
            <script>
              <uri>file://media/materials/scripts/gazebo.material</uri>
              <name>Gazebo/Grey</name>
            </script>
          </material>
        </visual>
        <self_collide>0</self_collide>
        <enable_wind>0</enable_wind>
        <kinematic>0</kinematic>
      </link>
    </model>
    <gravity>0 0 -9.8</gravity>
    <magnetic_field>6e-06 2.3e-05 -4.2e-05</magnetic_field>
    <atmosphere type='adiabatic'/>
    <physics type='ode'>
      <max_step_size>0.001</max_step_size>
      <real_time_factor>1</real_time_factor>
      <real_time_update_rate>1000</real_time_update_rate>
    </physics>
    <scene>
      <ambient>0.4 0.4 0.4 1</ambient>
      <background>0.7 0.7 0.7 1</background>
      <shadows>1</shadows>
    </scene>
    <audio>
      <device>default</device>
    </audio>
    <wind/>
    <spherical_coordinates>
      <surface_model>EARTH_WGS84</surface_model>
      <latitude_deg>0</latitude_deg>
      <longitude_deg>0</longitude_deg>
      <elevation>0</elevation>
      <heading_deg>0</heading_deg>
    </spherical_coordinates>
    <model name='pine_tree'>
      <static>1</static>
      <link name='link'>
        <collision name='collision'>
          <geometry>
            <mesh>
              <uri>model://pine_tree/meshes/pine_tree.dae</uri>
            </mesh>
          </geometry>
          <max_contacts>10</max_contacts>
          <surface>
            <contact>
              <ode/>
            </contact>
            <bounce/>
            <friction>
              <torsional>
                <ode/>
              </torsional>
              <ode/>
            </friction>
          </surface>
        </collision>
        <visual name='branch'>
          <geometry>
            <mesh>
              <uri>model://pine_tree/meshes/pine_tree.dae</uri>
              <submesh>
                <name>Branch</name>
              </submesh>
            </mesh>
          </geometry>
          <material>
            <script>
              <uri>model://pine_tree/materials/scripts/</uri>
              <uri>model://pine_tree/materials/textures/</uri>
              <name>PineTree/Branch</name>
            </script>
          </material>
        </visual>
        <visual name='bark'>
          <geometry>
            <mesh>
              <uri>model://pine_tree/meshes/pine_tree.dae</uri>
              <submesh>
                <name>Bark</name>
              </submesh>
            </mesh>
          </geometry>
          <material>
            <script>
              <uri>model://pine_tree/materials/scripts/</uri>
              <uri>model://pine_tree/materials/textures/</uri>
              <name>PineTree/Bark</name>
            </script>
          </material>
        </visual>
        <self_collide>0</self_collide>
        <enable_wind>0</enable_wind>
        <kinematic>0</kinematic>
      </link>
      <pose>-0.003078 5.22382 0 0 -0 0</pose>
    </model>
    <model name='pine_tree_0'>
      <static>1</static>
      <link name='link'>
        <collision name='collision'>
          <geometry>
            <mesh>
              <uri>model://pine_tree/meshes/pine_tree.dae</uri>
            </mesh>
          </geometry>
          <max_contacts>10</max_contacts>
          <surface>
            <contact>
              <ode/>
            </contact>
            <bounce/>
            <friction>
              <torsional>
                <ode/>
              </torsional>
              <ode/>
            </friction>
          </surface>
        </collision>
        <visual name='branch'>
          <geometry>
            <mesh>
              <uri>model://pine_tree/meshes/pine_tree.dae</uri>
              <submesh>
                <name>Branch</name>
              </submesh>
            </mesh>
          </geometry>
          <material>
            <script>
              <uri>model://pine_tree/materials/scripts/</uri>
              <uri>model://pine_tree/materials/textures/</uri>
              <name>PineTree/Branch</name>
            </script>
          </material>
        </visual>
        <visual name='bark'>
          <geometry>
            <mesh>
              <uri>model://pine_tree/meshes/pine_tree.dae</uri>
              <submesh>
                <name>Bark</name>
              </submesh>
            </mesh>
          </geometry>
          <material>
            <script>
              <uri>model://pine_tree/materials/scripts/</uri>
              <uri>model://pine_tree/materials/textures/</uri>
              <name>PineTree/Bark</name>
            </script>
          </material>
        </visual>
        <self_collide>0</self_collide>
        <enable_wind>0</enable_wind>
        <kinematic>0</kinematic>
      </link>
      <pose>-5.38737 0.788578 0 0 -0 0</pose>
    </model>
    <model name='pine_tree_1'>
      <static>1</static>
      <link name='link'>
        <collision name='collision'>
          <geometry>
            <mesh>
              <uri>model://pine_tree/meshes/pine_tree.dae</uri>
            </mesh>
          </geometry>
          <max_contacts>10</max_contacts>
          <surface>
            <contact>
              <ode/>
            </contact>
            <bounce/>
            <friction>
              <torsional>
                <ode/>
              </torsional>
              <ode/>
            </friction>
          </surface>
        </collision>
        <visual name='branch'>
          <geometry>
            <mesh>
              <uri>model://pine_tree/meshes/pine_tree.dae</uri>
              <submesh>
                <name>Branch</name>
              </submesh>
            </mesh>
          </geometry>
          <material>
            <script>
              <uri>model://pine_tree/materials/scripts/</uri>
              <uri>model://pine_tree/materials/textures/</uri>
              <name>PineTree/Branch</name>
            </script>
          </material>
        </visual>
        <visual name='bark'>
          <geometry>
            <mesh>
              <uri>model://pine_tree/meshes/pine_tree.dae</uri>
              <submesh>
                <name>Bark</name>
              </submesh>
            </mesh>
          </geometry>
          <material>
            <script>
              <uri>model://pine_tree/materials/scripts/</uri>
              <uri>model://pine_tree/materials/textures/</uri>
              <name>PineTree/Bark</name>
            </script>
          </material>
        </visual>
        <self_collide>0</self_collide>
        <enable_wind>0</enable_wind>
        <kinematic>0</kinematic>
      </link>
      <pose>-0.148604 -5.10518 0 0 -0 0</pose>
    </model>
    <model name='pine_tree_2'>
      <static>1</static>
      <link name='link'>
        <collision name='collision'>
          <geometry>
            <mesh>
              <uri>model://pine_tree/meshes/pine_tree.dae</uri>
            </mesh>
          </geometry>
          <max_contacts>10</max_contacts>
          <surface>
            <contact>
              <ode/>
            </contact>
            <bounce/>
            <friction>
              <torsional>
                <ode/>
              </torsional>
              <ode/>
            </friction>
          </surface>
        </collision>
        <visual name='branch'>
          <geometry>
            <mesh>
              <uri>model://pine_tree/meshes/pine_tree.dae</uri>
              <submesh>
                <name>Branch</name>
              </submesh>
            </mesh>
          </geometry>
          <material>
            <script>
              <uri>model://pine_tree/materials/scripts/</uri>
              <uri>model://pine_tree/materials/textures/</uri>
              <name>PineTree/Branch</name>
            </script>
          </material>
        </visual>
        <visual name='bark'>
          <geometry>
            <mesh>
              <uri>model://pine_tree/meshes/pine_tree.dae</uri>
              <submesh>
                <name>Bark</name>
              </submesh>
            </mesh>
          </geometry>
          <material>
            <script>
              <uri>model://pine_tree/materials/scripts/</uri>
              <uri>model://pine_tree/materials/textures/</uri>
              <name>PineTree/Bark</name>
            </script>
          </material>
        </visual>
        <self_collide>0</self_collide>
        <enable_wind>0</enable_wind>
        <kinematic>0</kinematic>
      </link>
      <pose>5.46827 -0.553032 0 0 -0 0</pose>
    </model>
    <state world_name='default'>
      <sim_time>622 975000000</sim_time>
      <real_time>295 589614154</real_time>
      <wall_time>1687197772 500742713</wall_time>
      <iterations>294536</iterations>
      <model name='car'>
        <pose>-0.100604 -0.112325 0.008836 -0.006493 -1e-06 0.127372</pose>
        <scale>1 1 1</scale>
        <link name='base_link'>
          <pose>-0.100604 -0.112325 0.008836 -0.006493 -1e-06 0.127372</pose>
          <velocity>-0.000577 -0.000344 -0.009191 0.001313 0.000211 0.000324</velocity>
          <acceleration>-0.002163 0.057164 -7.82798 2.09854 0.494019 0.007488</acceleration>
          <wrench>-0.002163 0.057164 -7.82798 0 -0 0</wrench>
        </link>
        <link name='bl_1'>
          <pose>-0.700189 -1.53149 0.342488 0.385946 -3e-06 0.127372</pose>
          <velocity>0.00012 -0.000982 -0.01173 0.001263 0.000788 0.00033</velocity>
          <acceleration>0.526023 -0.631578 -11.5763 1.13876 0.935904 2.96908</acceleration>
          <wrench>12.8876 -15.4737 -283.62 0 -0 0</wrench>
        </link>
        <link name='br_1'>
          <pose>0.837255 -1.33459 0.342489 -0.043905 -2e-06 0.127371</pose>
          <velocity>-2.2e-05 -0.000451 -0.011595 0.001292 0.000559 0.000387</velocity>
          <acceleration>0.382791 -0.629317 -11.472 -1.41374 1.53063 3.00622</acceleration>
          <wrench>9.37838 -15.4183 -281.065 0 -0 0</wrench>
        </link>
        <link name='chassis_link'>
          <pose>-0.100604 -0.112325 0.008836 -0.006493 -1e-06 0.127372</pose>
          <velocity>-0.000578 -0.000345 -0.009171 0.001337 0.000214 0.000323</velocity>
          <acceleration>-0.00207 0.058045 -7.80179 2.19839 -0.452105 0.04521</acceleration>
          <wrench>-3.26994 91.7111 -12326.8 0 -0 0</wrench>
        </link>
        <link name='fl_1'>
          <pose>-1.15387 1.2239 0.324561 0.001513 1.4e-05 0.132515</pose>
          <velocity>-0.000251 -0.003925 -0.058285 0.008403 0.0056 0.000252</velocity>
          <acceleration>-1.7581 0.945455 -69.2535 2.5804 1.54883 -2.66515</acceleration>
          <wrench>-43.0735 23.1637 -1696.71 0 -0 0</wrench>
        </link>
        <link name='fr_1'>
          <pose>0.581899 1.44657 0.324561 -0.001583 -3e-06 0.130222</pose>
          <velocity>-0.000628 0.001579 -0.058622 -0.009664 0.004052 0.000448</velocity>
          <acceleration>1.02507 -3.30229 -69.2348 1.79482 0.853052 -2.2137</acceleration>
          <wrench>25.1143 -80.9062 -1696.25 0 -0 0</wrench>
        </link>
        <link name='l_steer_1'>
          <pose>-1.10431 1.23051 0.324627 -0.006493 3.5e-05 0.132515</pose>
          <velocity>-5.4e-05 -0.00473 -0.075838 0.001289 -0.000528 0.000322</velocity>
          <acceleration>-2.31498 1.36116 -91.8116 -0.525529 -0.057892 -2.95905</acceleration>
          <wrench>-2.31498 1.36116 -91.8116 0 -0 0</wrench>
        </link>
        <link name='lidar_link'>
          <pose>-0.100604 -0.112309 0.008836 -0.006489 -1e-06 0.127372</pose>
          <velocity>-0.001056 0.000729 -0.009237 0.001574 0.000333 0.000324</velocity>
          <acceleration>0.076006 -2.74017 -7.85512 1.92996 0.674733 0.006552</acceleration>
          <wrench>0.008665 -0.312379 -0.895484 0 -0 0</wrench>
        </link>
        <link name='r_steer_1'>
          <pose>0.532322 1.44008 0.32463 -0.006494 8e-06 0.130222</pose>
          <velocity>-0.000567 0.002034 -0.076347 0.001093 0.002813 0.000305</velocity>
          <acceleration>1.2755 -4.24373 -92.0507 -1.63544 -1.52806 -1.47807</acceleration>
          <wrench>1.2755 -4.24373 -92.0507 0 -0 0</wrench>
        </link>
        <link name='steering_wheel'>
          <pose>-0.100604 -0.112322 0.008835 -0.011236 1.5e-05 0.128678</pose>
          <velocity>-0.00058 -0.000343 -0.009061 0.000158 6.6e-05 0.000669</velocity>
          <acceleration>-0.003739 0.06118 -7.66158 0.129678 0.25657 0.586264</acceleration>
          <wrench>-0.003739 0.06118 -7.66158 0 -0 0</wrench>
        </link>
      </model>
      <model name='ground_plane'>
        <pose>0 0 0 0 -0 0</pose>
        <scale>1 1 1</scale>
        <link name='link'>
          <pose>0 0 0 0 -0 0</pose>
          <velocity>0 0 0 0 -0 0</velocity>
          <acceleration>0 0 0 0 -0 0</acceleration>
          <wrench>0 0 0 0 -0 0</wrench>
        </link>
      </model>
      <model name='pine_tree'>
        <pose>-0.003078 7.13078 0 0 -0 0</pose>
        <scale>1 1 1</scale>
        <link name='link'>
          <pose>-0.003078 7.13078 0 0 -0 0</pose>
          <velocity>0 0 0 0 -0 0</velocity>
          <acceleration>0 0 0 0 -0 0</acceleration>
          <wrench>0 0 0 0 -0 0</wrench>
        </link>
      </model>
      <light name='sun'>
        <pose>0 0 10 0 -0 0</pose>
      </light>
    </state>
    <gui fullscreen='0'>
      <camera name='user_camera'>
        <pose>-1.99285 -23.2576 59.6736 -0 1.11283 1.71238</pose>
        <view_controller>orbit</view_controller>
        <projection_type>perspective</projection_type>
      </camera>
    </gui>
    <model name='car'>
      <pose>0 0 0 0 -0 0</pose>
      <link name='base_link'>
        <self_collide>0</self_collide>
        <inertial>
          <pose>0 0 0 0 -0 0</pose>
          <inertia>
            <ixx>1</ixx>
            <ixy>0</ixy>
            <ixz>0</ixz>
            <iyy>1</iyy>
            <iyz>0</iyz>
            <izz>1</izz>
          </inertia>
          <mass>1</mass>
        </inertial>
        <enable_wind>0</enable_wind>
        <kinematic>0</kinematic>
      </link>
      <joint name='chassis_link_joint' type='fixed'>
        <pose>0 0 0 0 -0 0</pose>
        <parent>base_link</parent>
        <child>chassis_link</child>
      </joint>
      <link name='chassis_link'>
        <inertial>
          <pose>0 0 0 0 -0 0</pose>
          <mass>1580</mass>
          <inertia>
            <ixx>1997.86</ixx>
            <ixy>-3e-05</ixy>
            <ixz>-1e-06</ixz>
            <iyy>442.769</iyy>
            <iyz>62.5206</iyz>
            <izz>2238.05</izz>
          </inertia>
        </inertial>
        <collision name='chassis_link_fixed_joint_lump__chassis_link_collision'>
          <pose>0 0 0 0 -0 0</pose>
          <geometry>
            <mesh>
              <scale>1 1 1</scale>
              <uri>model://ackerman_car/car/meshes/body.dae</uri>
            </mesh>
          </geometry>
          <surface>
            <contact>
              <ode/>
            </contact>
            <friction>
              <ode>
                <mu>0.2</mu>
                <mu2>0.2</mu2>
              </ode>
              <torsional>
                <ode/>
              </torsional>
            </friction>
            <bounce/>
          </surface>
          <max_contacts>10</max_contacts>
        </collision>
        <visual name='chassis_link_fixed_joint_lump__chassis_link_visual'>
          <pose>0 0 0 0 -0 1.57</pose>
          <geometry>
            <mesh>
              <scale>1 1 1</scale>
              <uri>model://ackerman_car/car/meshes/body.dae</uri>
            </mesh>
          </geometry>
        </visual>
        <self_collide>1</self_collide>
        <enable_wind>0</enable_wind>
        <kinematic>0</kinematic>
      </link>
      <joint name='lidar_joint' type='fixed'>
        <parent>base_link</parent>
        <child>lidar_link</child>
        <pose>0 0 1.2 0 -0 0</pose>
        <axis>
          <xyz>0 0 1</xyz>
          <limit>
            <lower>-1e+16</lower>
            <upper>1e+16</upper>
          </limit>
        </axis>
      </joint>
      <link name='lidar_link'>
        <inertial>
          <pose>0 0 1.16 0 -0 0</pose>
          <inertia>
            <ixx>0.001</ixx>
            <ixy>0</ixy>
            <ixz>0</ixz>
            <iyy>0.001</iyy>
            <iyz>0</iyz>
            <izz>0.001</izz>
          </inertia>
          <mass>0.114</mass>
        </inertial>
        <collision name='lidar_collision'>
          <pose>0 0 1.16 0 -0 0</pose>
          <geometry>
            <cylinder>
              <radius>0.0508</radius>
              <length>0.18</length>
            </cylinder>
          </geometry>
          <max_contacts>10</max_contacts>
          <surface>
            <contact>
              <ode/>
            </contact>
            <bounce/>
            <friction>
              <torsional>
                <ode/>
              </torsional>
              <ode/>
            </friction>
          </surface>
        </collision>
        <visual name='lidar_visual'>
          <pose>0 0 1.45 0 -0 0</pose>
          <geometry>
            <cylinder>
              <radius>0.0508</radius>
              <length>0.18</length>
            </cylinder>
          </geometry>
          <material>
            <ambient>0 0 0 1</ambient>
            <diffuse>0 0 0 1</diffuse>
            <specular>0 0 0 1</specular>
            <emissive>0 0 0 1</emissive>
          </material>
        </visual>
        <sensor name='lidar' type='ray'>
          <pose>0 0 1.55 0 -0 0</pose>
          <visualize>true</visualize>
          <update_rate>20</update_rate>
          <ray>
            <scan>
              <horizontal>
                <samples>200</samples>
                <resolution>1.0</resolution>
                <min_angle>0.785398</min_angle>
                <max_angle>2.35619</max_angle>
              </horizontal>
            </scan>
            <range>
              <min>0.12</min>
              <max>30</max>
              <resolution>0.015</resolution>
            </range>
            <noise>
              <type>gaussian</type>
              <mean>0</mean>
              <stddev>0.01</stddev>
            </noise>
          </ray>
          <plugin name='scan' filename='libgazebo_ros_ray_sensor.so'>
            <ros>
              <namespace>car</namespace>
              <remapping>~/out:=scan</remapping>
            </ros>
            <output_type>sensor_msgs/LaserScan</output_type>
            <frame_name>lidar_link</frame_name>
          </plugin>
        </sensor>
        <self_collide>0</self_collide>
        <enable_wind>0</enable_wind>
        <kinematic>0</kinematic>
      </link>
      <joint name='bl_axle' type='revolute'>
        <pose relative_to='chassis_link'>-0.775 -1.33364 0.324997 0 -0 0</pose>
        <parent>chassis_link</parent>
        <child>bl_1</child>
        <axis>
          <xyz>-1 0 0</xyz>
          <dynamics>
            <friction>12.0316</friction>
            <spring_reference>0</spring_reference>
            <spring_stiffness>0</spring_stiffness>
          </dynamics>
          <limit>
            <lower>-1e+16</lower>
            <upper>1e+16</upper>
          </limit>
        </axis>
      </joint>
      <link name='bl_1'>
        <pose relative_to='bl_axle'>0 0 0 0 -0 0</pose>
        <inertial>
          <pose>-0.0377 0 -0 0 -0 0</pose>
          <mass>24.5</mass>
          <inertia>
            <ixx>1.84514</ixx>
            <ixy>0</ixy>
            <ixz>0</ixz>
            <iyy>1.04961</iyy>
            <iyz>0</iyz>
            <izz>1.04961</izz>
          </inertia>
        </inertial>
        <collision name='bl_1_collision'>
          <pose relative_to='bl_axle'>0 0 0 3.14159 1.57079 3.14159</pose>
          <geometry>
            <cylinder>
              <radius>0.3425</radius>
              <length>0.22</length>
            </cylinder>
          </geometry>
          <surface>
            <contact>
              <ode/>
            </contact>
            <friction>
              <ode>
                <mu>1.7</mu>
                <mu2>1.7</mu2>
              </ode>
              <torsional>
                <ode/>
              </torsional>
            </friction>
            <bounce/>
          </surface>
          <max_contacts>10</max_contacts>
        </collision>
        <visual name='bl_1_visual'>
          <pose>0.875 1.0136 0.1444 0 -0 0</pose>
          <geometry>
            <mesh>
              <scale>0.1 0.1 0.1</scale>
              <uri>model://ackerman_car/car/meshes/back_left.dae</uri>
            </mesh>
          </geometry>
        </visual>
        <self_collide>0</self_collide>
        <enable_wind>0</enable_wind>
        <kinematic>0</kinematic>
      </link>
      <joint name='br_axle' type='revolute'>
        <pose relative_to='chassis_link'>0.775 -1.33364 0.324997 0 -0 0</pose>
        <parent>chassis_link</parent>
        <child>br_1</child>
        <axis>
          <xyz>-1 0 0</xyz>
          <dynamics>
            <friction>12.0316</friction>
            <spring_reference>0</spring_reference>
            <spring_stiffness>0</spring_stiffness>
          </dynamics>
          <limit>
            <lower>-1e+16</lower>
            <upper>1e+16</upper>
          </limit>
        </axis>
      </joint>
      <link name='br_1'>
        <pose relative_to='br_axle'>0 0 0 0 -0 0</pose>
        <inertial>
          <pose>-0.0377 0 -0 0 -0 0</pose>
          <mass>24.5</mass>
          <inertia>
            <ixx>1.84514</ixx>
            <ixy>0</ixy>
            <ixz>0</ixz>
            <iyy>1.04961</iyy>
            <iyz>0</iyz>
            <izz>1.04961</izz>
          </inertia>
        </inertial>
        <collision name='br_1_collision'>
          <pose relative_to='br_axle'>0 0 0 3.14159 1.57079 3.14159</pose>
          <geometry>
            <cylinder>
              <radius>0.3425</radius>
              <length>0.22</length>
            </cylinder>
          </geometry>
          <surface>
            <contact>
              <ode/>
            </contact>
            <friction>
              <ode>
                <mu>1.7</mu>
                <mu2>1.7</mu2>
              </ode>
              <torsional>
                <ode/>
              </torsional>
            </friction>
            <bounce/>
          </surface>
          <max_contacts>10</max_contacts>
        </collision>
        <visual name='br_1_visual'>
          <pose>-0.875 1.0136 0.1444 0 -0 0</pose>
          <geometry>
            <mesh>
              <scale>0.1 0.1 0.1</scale>
              <uri>model://ackerman_car/car/meshes/back_right.dae</uri>
            </mesh>
          </geometry>
        </visual>
        <self_collide>0</self_collide>
        <enable_wind>0</enable_wind>
        <kinematic>0</kinematic>
      </link>
      <joint name='l_steer' type='revolute'>
        <pose relative_to='chassis_link'>-0.825 1.45736 0.324997 0 -0 0</pose>
        <parent>chassis_link</parent>
        <child>l_steer_1</child>
        <axis>
          <xyz>0 0 1</xyz>
          <limit>
            <lower>-0.95</lower>
            <upper>0.95</upper>
          </limit>
          <dynamics>
            <friction>18.0474</friction>
            <spring_reference>0</spring_reference>
            <spring_stiffness>0</spring_stiffness>
          </dynamics>
        </axis>
      </joint>
      <link name='l_steer_1'>
        <pose relative_to='l_steer'>0 0 0 0 -0 0</pose>
        <inertial>
          <pose>0.003381 0 0.02162 0 -0 0</pose>
          <mass>1</mass>
          <inertia>
            <ixx>1</ixx>
            <ixy>0</ixy>
            <ixz>0</ixz>
            <iyy>1</iyy>
            <iyz>0</iyz>
            <izz>1</izz>
          </inertia>
        </inertial>
        <self_collide>0</self_collide>
        <enable_wind>0</enable_wind>
        <kinematic>0</kinematic>
      </link>
      <joint name='fl_axle' type='revolute'>
        <pose relative_to='l_steer_1'>-0.05 0 0 0 -0 0</pose>
        <parent>l_steer_1</parent>
        <child>fl_1</child>
        <axis>
          <xyz>-1 0 0</xyz>
          <dynamics>
            <friction>12.0316</friction>
            <spring_reference>0</spring_reference>
            <spring_stiffness>0</spring_stiffness>
          </dynamics>
          <limit>
            <lower>-1e+16</lower>
            <upper>1e+16</upper>
          </limit>
        </axis>
      </joint>
      <link name='fl_1'>
        <pose relative_to='fl_axle'>0 0 0 0 -0 0</pose>
        <inertial>
          <pose>-0.0377 0 -0 0 -0 0</pose>
          <mass>24.5</mass>
          <inertia>
            <ixx>1.84514</ixx>
            <ixy>0</ixy>
            <ixz>0</ixz>
            <iyy>1.04961</iyy>
            <iyz>0</iyz>
            <izz>1.04961</izz>
          </inertia>
        </inertial>
        <collision name='fl_1_collision'>
          <pose>0.875 -1.5174 0.1444 0 -0 0</pose>
          <geometry>
            <mesh>
              <scale>0.001 0.001 0.001</scale>
              <uri>model://ackerman_car/car/meshes/fl_1.stl</uri>
            </mesh>
          </geometry>
          <surface>
            <contact>
              <ode/>
            </contact>
            <friction>
              <ode>
                <mu>1.1</mu>
                <mu2>1.1</mu2>
              </ode>
              <torsional>
                <ode/>
              </torsional>
            </friction>
            <bounce/>
          </surface>
          <max_contacts>10</max_contacts>
        </collision>
        <visual name='fl_1_visual'>
          <pose>0.875 -1.5174 0.1444 0 -0 0</pose>
          <geometry>
            <mesh>
              <scale>0.1 0.1 0.1</scale>
              <uri>model://ackerman_car/car/meshes/front_left.dae</uri>
            </mesh>
          </geometry>
        </visual>
        <self_collide>0</self_collide>
        <enable_wind>0</enable_wind>
        <kinematic>0</kinematic>
      </link>
      <joint name='r_steer' type='revolute'>
        <pose relative_to='chassis_link'>0.825 1.45736 0.324997 0 -0 0</pose>
        <parent>chassis_link</parent>
        <child>r_steer_1</child>
        <axis>
          <xyz>0 0 1</xyz>
          <limit>
            <lower>-0.95</lower>
            <upper>0.95</upper>
          </limit>
          <dynamics>
            <damping>0.01</damping>
            <friction>18.0474</friction>
            <spring_reference>0</spring_reference>
            <spring_stiffness>0</spring_stiffness>
          </dynamics>
        </axis>
      </joint>
      <link name='r_steer_1'>
        <pose relative_to='r_steer'>0 0 0 0 -0 0</pose>
        <inertial>
          <pose>0.003381 0 0.02162 0 -0 0</pose>
          <mass>1</mass>
          <inertia>
            <ixx>1</ixx>
            <ixy>0</ixy>
            <ixz>0</ixz>
            <iyy>1</iyy>
            <iyz>0</iyz>
            <izz>1</izz>
          </inertia>
        </inertial>
        <self_collide>0</self_collide>
        <enable_wind>0</enable_wind>
        <kinematic>0</kinematic>
      </link>
      <joint name='fr_axle' type='revolute'>
        <pose relative_to='r_steer_1'>0.05 0 0 0 -0 0</pose>
        <parent>r_steer_1</parent>
        <child>fr_1</child>
        <axis>
          <xyz>-1 0 0</xyz>
          <dynamics>
            <friction>12.0316</friction>
            <spring_reference>0</spring_reference>
            <spring_stiffness>0</spring_stiffness>
          </dynamics>
          <limit>
            <lower>-1e+16</lower>
            <upper>1e+16</upper>
          </limit>
        </axis>
      </joint>
      <link name='fr_1'>
        <pose relative_to='fr_axle'>0 0 0 0 -0 0</pose>
        <inertial>
          <pose>-0.0377 0 -0 0 -0 0</pose>
          <mass>24.5</mass>
          <inertia>
            <ixx>1.84514</ixx>
            <ixy>0</ixy>
            <ixz>0</ixz>
            <iyy>1.04961</iyy>
            <iyz>0</iyz>
            <izz>1.04961</izz>
          </inertia>
        </inertial>
        <collision name='fr_1_collision'>
          <pose>-0.875 -1.5174 0.1444 0 -0 0</pose>
          <geometry>
            <mesh>
              <scale>0.001 0.001 0.001</scale>
              <uri>model://ackerman_car/car/meshes/fr_1.stl</uri>
            </mesh>
          </geometry>
          <surface>
            <contact>
              <ode/>
            </contact>
            <friction>
              <ode>
                <mu>1.7</mu>
                <mu2>1.7</mu2>
              </ode>
              <torsional>
                <ode/>
              </torsional>
            </friction>
            <bounce/>
          </surface>
          <max_contacts>10</max_contacts>
        </collision>
        <visual name='fr_1_visual'>
          <pose>-0.875 -1.5174 0.1444 0 -0 0</pose>
          <geometry>
            <mesh>
              <scale>0.1 0.1 0.1</scale>
              <uri>model://ackerman_car/car/meshes/front_right.dae</uri>
            </mesh>
          </geometry>
        </visual>
        <self_collide>0</self_collide>
        <enable_wind>0</enable_wind>
        <kinematic>0</kinematic>
      </link>
      <link name='steering_wheel'>
        <self_collide>0</self_collide>
        <inertial>
          <pose>0 0 0 0 -0 0</pose>
          <inertia>
            <ixx>1</ixx>
            <ixy>0</ixy>
            <ixz>0</ixz>
            <iyy>1</iyy>
            <iyz>0</iyz>
            <izz>1</izz>
          </inertia>
          <mass>1</mass>
        </inertial>
        <enable_wind>0</enable_wind>
        <kinematic>0</kinematic>
      </link>
      <joint name='steering_joint' type='revolute'>
        <pose>-0.002 0 0 0 -0 0</pose>
        <parent>chassis_link</parent>
        <child>steering_wheel</child>
        <axis>
          <xyz expressed_in='__model__'>-0.964118 0.000768 0.265556</xyz>
          <limit>
            <lower>-100</lower>
            <upper>100</upper>
          </limit>
          <dynamics>
            <damping>1</damping>
            <spring_reference>0</spring_reference>
            <spring_stiffness>0</spring_stiffness>
          </dynamics>
        </axis>
        <physics>
          <ode>
            <cfm_damping>1</cfm_damping>
            <limit>
              <cfm>0</cfm>
              <erp>0.2</erp>
            </limit>
          </ode>
        </physics>
      </joint>
      <plugin name='ackermann_drive' filename='libgazebo_ros_ackermann_drive.so'>
        <ros>
          <namespace>car</namespace>
          <remapping>cmd_vel:=cmd_vel</remapping>
          <remapping>odom:=odom</remapping>
          <remapping>distance:=distance</remapping>
        </ros>
        <update_rate>100.0</update_rate>
        <front_left_joint>fl_axle</front_left_joint>
        <front_right_joint>fr_axle</front_right_joint>
        <rear_left_joint>bl_axle</rear_left_joint>
        <rear_right_joint>br_axle</rear_right_joint>
        <left_steering_joint>l_steer</left_steering_joint>
        <right_steering_joint>r_steer</right_steering_joint>
        <steering_wheel_joint>steering_joint</steering_wheel_joint>
        <max_steer>0.52</max_steer>
        <max_steering_angle>0.64</max_steering_angle>
        <max_speed>50</max_speed>
        <left_steering_pid_gain>1500 900 450</left_steering_pid_gain>
        <left_steering_i_range>0 0</left_steering_i_range>
        <right_steering_pid_gain>1500 900 450</right_steering_pid_gain>
        <right_steering_i_range>0 0</right_steering_i_range>
        <linear_velocity_pid_gain>1000 100 10</linear_velocity_pid_gain>
        <linear_velocity_i_range>0 0</linear_velocity_i_range>
        <publish_odom>1</publish_odom>
        <publish_odom_tf>1</publish_odom_tf>
        <publish_wheel_tf>1</publish_wheel_tf>
        <publish_distance>1</publish_distance>
        <odometry_frame>odom</odometry_frame>
        <robot_base_frame>chassis_link</robot_base_frame>
      </plugin>
    </model>
  </world>
</sdf>
